Not Found: /media/planilla_44.pdf
Not Found: /media/planilla_44.pdf
Watching for file changes with StatReloader
"GET /excel/pdfs/ HTTP/1.1" 200 14673
Not Found: /media/planilla_44.pdf
"GET /media/planilla_44.pdf HTTP/1.1" 404 179
Watching for file changes with StatReloader
"GET /media/planilla_44.pdf HTTP/1.1" 200 12963
"GET /media/planilla_43.pdf HTTP/1.1" 200 2164
Watching for file changes with StatReloader
Not Found: /favicon.ico
Internal Server Error: /excel/upload/
Traceback (most recent call last):
  File "/home/sebastian11/venv/lib/python3.12/site-packages/django/db/backends/utils.py", line 105, in _execute
    return self.cursor.execute(sql, params)
           ^^^^^^^^^^^^^^^^^^^^^^^^^^^^^^^^
  File "/home/sebastian11/venv/lib/python3.12/site-packages/django/db/backends/sqlite3/base.py", line 360, in execute
    return super().execute(query, params)
           ^^^^^^^^^^^^^^^^^^^^^^^^^^^^^^
sqlite3.OperationalError: attempt to write a readonly database

The above exception was the direct cause of the following exception:

Traceback (most recent call last):
  File "/home/sebastian11/venv/lib/python3.12/site-packages/django/core/handlers/exception.py", line 55, in inner
    response = get_response(request)
               ^^^^^^^^^^^^^^^^^^^^^
  File "/home/sebastian11/venv/lib/python3.12/site-packages/django/core/handlers/base.py", line 197, in _get_response
    response = wrapped_callback(request, *callback_args, **callback_kwargs)
               ^^^^^^^^^^^^^^^^^^^^^^^^^^^^^^^^^^^^^^^^^^^^^^^^^^^^^^^^^^^^
  File "/var/www/mi_django_app/excel_processor/views.py", line 152, in upload_excel_web
    excel_obj_3_7 = ExcelProcess.objects.create(archivo=archivo, consecutivo=consecutivo_3_7)
                    ^^^^^^^^^^^^^^^^^^^^^^^^^^^^^^^^^^^^^^^^^^^^^^^^^^^^^^^^^^^^^^^^^^^^^^^^^
  File "/home/sebastian11/venv/lib/python3.12/site-packages/django/db/models/manager.py", line 87, in manager_method
    return getattr(self.get_queryset(), name)(*args, **kwargs)
           ^^^^^^^^^^^^^^^^^^^^^^^^^^^^^^^^^^^^^^^^^^^^^^^^^^^
  File "/home/sebastian11/venv/lib/python3.12/site-packages/django/db/models/query.py", line 663, in create
    obj.save(force_insert=True, using=self.db)
  File "/home/sebastian11/venv/lib/python3.12/site-packages/django/db/models/base.py", line 902, in save
    self.save_base(
  File "/home/sebastian11/venv/lib/python3.12/site-packages/django/db/models/base.py", line 1008, in save_base
    updated = self._save_table(
              ^^^^^^^^^^^^^^^^^
  File "/home/sebastian11/venv/lib/python3.12/site-packages/django/db/models/base.py", line 1169, in _save_table
    results = self._do_insert(
              ^^^^^^^^^^^^^^^^
  File "/home/sebastian11/venv/lib/python3.12/site-packages/django/db/models/base.py", line 1210, in _do_insert
    return manager._insert(
           ^^^^^^^^^^^^^^^^
  File "/home/sebastian11/venv/lib/python3.12/site-packages/django/db/models/manager.py", line 87, in manager_method
    return getattr(self.get_queryset(), name)(*args, **kwargs)
           ^^^^^^^^^^^^^^^^^^^^^^^^^^^^^^^^^^^^^^^^^^^^^^^^^^^
  File "/home/sebastian11/venv/lib/python3.12/site-packages/django/db/models/query.py", line 1864, in _insert
    return query.get_compiler(using=using).execute_sql(returning_fields)
           ^^^^^^^^^^^^^^^^^^^^^^^^^^^^^^^^^^^^^^^^^^^^^^^^^^^^^^^^^^^^^
  File "/home/sebastian11/venv/lib/python3.12/site-packages/django/db/models/sql/compiler.py", line 1882, in execute_sql
    cursor.execute(sql, params)
  File "/home/sebastian11/venv/lib/python3.12/site-packages/django/db/backends/utils.py", line 79, in execute
    return self._execute_with_wrappers(
           ^^^^^^^^^^^^^^^^^^^^^^^^^^^^
  File "/home/sebastian11/venv/lib/python3.12/site-packages/django/db/backends/utils.py", line 92, in _execute_with_wrappers
    return executor(sql, params, many, context)
           ^^^^^^^^^^^^^^^^^^^^^^^^^^^^^^^^^^^^
  File "/home/sebastian11/venv/lib/python3.12/site-packages/django/db/backends/utils.py", line 100, in _execute
    with self.db.wrap_database_errors:
  File "/home/sebastian11/venv/lib/python3.12/site-packages/django/db/utils.py", line 91, in __exit__
    raise dj_exc_value.with_traceback(traceback) from exc_value
  File "/home/sebastian11/venv/lib/python3.12/site-packages/django/db/backends/utils.py", line 105, in _execute
    return self.cursor.execute(sql, params)
           ^^^^^^^^^^^^^^^^^^^^^^^^^^^^^^^^
  File "/home/sebastian11/venv/lib/python3.12/site-packages/django/db/backends/sqlite3/base.py", line 360, in execute
    return super().execute(query, params)
           ^^^^^^^^^^^^^^^^^^^^^^^^^^^^^^
django.db.utils.OperationalError: attempt to write a readonly database
Internal Server Error: /excel/upload/
Traceback (most recent call last):
  File "/home/sebastian11/venv/lib/python3.12/site-packages/django/db/backends/utils.py", line 105, in _execute
    return self.cursor.execute(sql, params)
           ^^^^^^^^^^^^^^^^^^^^^^^^^^^^^^^^
  File "/home/sebastian11/venv/lib/python3.12/site-packages/django/db/backends/sqlite3/base.py", line 360, in execute
    return super().execute(query, params)
           ^^^^^^^^^^^^^^^^^^^^^^^^^^^^^^
sqlite3.OperationalError: attempt to write a readonly database

The above exception was the direct cause of the following exception:

Traceback (most recent call last):
  File "/home/sebastian11/venv/lib/python3.12/site-packages/django/core/handlers/exception.py", line 55, in inner
    response = get_response(request)
               ^^^^^^^^^^^^^^^^^^^^^
  File "/home/sebastian11/venv/lib/python3.12/site-packages/django/core/handlers/base.py", line 197, in _get_response
    response = wrapped_callback(request, *callback_args, **callback_kwargs)
               ^^^^^^^^^^^^^^^^^^^^^^^^^^^^^^^^^^^^^^^^^^^^^^^^^^^^^^^^^^^^
  File "/var/www/mi_django_app/excel_processor/views.py", line 152, in upload_excel_web
    excel_obj_3_7 = ExcelProcess.objects.create(archivo=archivo, consecutivo=consecutivo_3_7)
                    ^^^^^^^^^^^^^^^^^^^^^^^^^^^^^^^^^^^^^^^^^^^^^^^^^^^^^^^^^^^^^^^^^^^^^^^^^
  File "/home/sebastian11/venv/lib/python3.12/site-packages/django/db/models/manager.py", line 87, in manager_method
    return getattr(self.get_queryset(), name)(*args, **kwargs)
           ^^^^^^^^^^^^^^^^^^^^^^^^^^^^^^^^^^^^^^^^^^^^^^^^^^^
  File "/home/sebastian11/venv/lib/python3.12/site-packages/django/db/models/query.py", line 663, in create
    obj.save(force_insert=True, using=self.db)
  File "/home/sebastian11/venv/lib/python3.12/site-packages/django/db/models/base.py", line 902, in save
    self.save_base(
  File "/home/sebastian11/venv/lib/python3.12/site-packages/django/db/models/base.py", line 1008, in save_base
    updated = self._save_table(
              ^^^^^^^^^^^^^^^^^
  File "/home/sebastian11/venv/lib/python3.12/site-packages/django/db/models/base.py", line 1169, in _save_table
    results = self._do_insert(
              ^^^^^^^^^^^^^^^^
  File "/home/sebastian11/venv/lib/python3.12/site-packages/django/db/models/base.py", line 1210, in _do_insert
    return manager._insert(
           ^^^^^^^^^^^^^^^^
  File "/home/sebastian11/venv/lib/python3.12/site-packages/django/db/models/manager.py", line 87, in manager_method
    return getattr(self.get_queryset(), name)(*args, **kwargs)
           ^^^^^^^^^^^^^^^^^^^^^^^^^^^^^^^^^^^^^^^^^^^^^^^^^^^
  File "/home/sebastian11/venv/lib/python3.12/site-packages/django/db/models/query.py", line 1864, in _insert
    return query.get_compiler(using=using).execute_sql(returning_fields)
           ^^^^^^^^^^^^^^^^^^^^^^^^^^^^^^^^^^^^^^^^^^^^^^^^^^^^^^^^^^^^^
  File "/home/sebastian11/venv/lib/python3.12/site-packages/django/db/models/sql/compiler.py", line 1882, in execute_sql
    cursor.execute(sql, params)
  File "/home/sebastian11/venv/lib/python3.12/site-packages/django/db/backends/utils.py", line 79, in execute
    return self._execute_with_wrappers(
           ^^^^^^^^^^^^^^^^^^^^^^^^^^^^
  File "/home/sebastian11/venv/lib/python3.12/site-packages/django/db/backends/utils.py", line 92, in _execute_with_wrappers
    return executor(sql, params, many, context)
           ^^^^^^^^^^^^^^^^^^^^^^^^^^^^^^^^^^^^
  File "/home/sebastian11/venv/lib/python3.12/site-packages/django/db/backends/utils.py", line 100, in _execute
    with self.db.wrap_database_errors:
  File "/home/sebastian11/venv/lib/python3.12/site-packages/django/db/utils.py", line 91, in __exit__
    raise dj_exc_value.with_traceback(traceback) from exc_value
  File "/home/sebastian11/venv/lib/python3.12/site-packages/django/db/backends/utils.py", line 105, in _execute
    return self.cursor.execute(sql, params)
           ^^^^^^^^^^^^^^^^^^^^^^^^^^^^^^^^
  File "/home/sebastian11/venv/lib/python3.12/site-packages/django/db/backends/sqlite3/base.py", line 360, in execute
    return super().execute(query, params)
           ^^^^^^^^^^^^^^^^^^^^^^^^^^^^^^
django.db.utils.OperationalError: attempt to write a readonly database
Not Found: /favicon.ico
Internal Server Error: /excel/upload/
Traceback (most recent call last):
  File "/home/sebastian11/venv/lib/python3.12/site-packages/django/db/backends/utils.py", line 105, in _execute
    return self.cursor.execute(sql, params)
           ^^^^^^^^^^^^^^^^^^^^^^^^^^^^^^^^
  File "/home/sebastian11/venv/lib/python3.12/site-packages/django/db/backends/sqlite3/base.py", line 360, in execute
    return super().execute(query, params)
           ^^^^^^^^^^^^^^^^^^^^^^^^^^^^^^
sqlite3.OperationalError: attempt to write a readonly database

The above exception was the direct cause of the following exception:

Traceback (most recent call last):
  File "/home/sebastian11/venv/lib/python3.12/site-packages/django/core/handlers/exception.py", line 55, in inner
    response = get_response(request)
               ^^^^^^^^^^^^^^^^^^^^^
  File "/home/sebastian11/venv/lib/python3.12/site-packages/django/core/handlers/base.py", line 197, in _get_response
    response = wrapped_callback(request, *callback_args, **callback_kwargs)
               ^^^^^^^^^^^^^^^^^^^^^^^^^^^^^^^^^^^^^^^^^^^^^^^^^^^^^^^^^^^^
  File "/var/www/mi_django_app/excel_processor/views.py", line 152, in upload_excel_web
    excel_obj_3_7 = ExcelProcess.objects.create(archivo=archivo, consecutivo=consecutivo_3_7)
                    ^^^^^^^^^^^^^^^^^^^^^^^^^^^^^^^^^^^^^^^^^^^^^^^^^^^^^^^^^^^^^^^^^^^^^^^^^
  File "/home/sebastian11/venv/lib/python3.12/site-packages/django/db/models/manager.py", line 87, in manager_method
    return getattr(self.get_queryset(), name)(*args, **kwargs)
           ^^^^^^^^^^^^^^^^^^^^^^^^^^^^^^^^^^^^^^^^^^^^^^^^^^^
  File "/home/sebastian11/venv/lib/python3.12/site-packages/django/db/models/query.py", line 663, in create
    obj.save(force_insert=True, using=self.db)
  File "/home/sebastian11/venv/lib/python3.12/site-packages/django/db/models/base.py", line 902, in save
    self.save_base(
  File "/home/sebastian11/venv/lib/python3.12/site-packages/django/db/models/base.py", line 1008, in save_base
    updated = self._save_table(
              ^^^^^^^^^^^^^^^^^
  File "/home/sebastian11/venv/lib/python3.12/site-packages/django/db/models/base.py", line 1169, in _save_table
    results = self._do_insert(
              ^^^^^^^^^^^^^^^^
  File "/home/sebastian11/venv/lib/python3.12/site-packages/django/db/models/base.py", line 1210, in _do_insert
    return manager._insert(
           ^^^^^^^^^^^^^^^^
  File "/home/sebastian11/venv/lib/python3.12/site-packages/django/db/models/manager.py", line 87, in manager_method
    return getattr(self.get_queryset(), name)(*args, **kwargs)
           ^^^^^^^^^^^^^^^^^^^^^^^^^^^^^^^^^^^^^^^^^^^^^^^^^^^
  File "/home/sebastian11/venv/lib/python3.12/site-packages/django/db/models/query.py", line 1864, in _insert
    return query.get_compiler(using=using).execute_sql(returning_fields)
           ^^^^^^^^^^^^^^^^^^^^^^^^^^^^^^^^^^^^^^^^^^^^^^^^^^^^^^^^^^^^^
  File "/home/sebastian11/venv/lib/python3.12/site-packages/django/db/models/sql/compiler.py", line 1882, in execute_sql
    cursor.execute(sql, params)
  File "/home/sebastian11/venv/lib/python3.12/site-packages/django/db/backends/utils.py", line 79, in execute
    return self._execute_with_wrappers(
           ^^^^^^^^^^^^^^^^^^^^^^^^^^^^
  File "/home/sebastian11/venv/lib/python3.12/site-packages/django/db/backends/utils.py", line 92, in _execute_with_wrappers
    return executor(sql, params, many, context)
           ^^^^^^^^^^^^^^^^^^^^^^^^^^^^^^^^^^^^
  File "/home/sebastian11/venv/lib/python3.12/site-packages/django/db/backends/utils.py", line 100, in _execute
    with self.db.wrap_database_errors:
  File "/home/sebastian11/venv/lib/python3.12/site-packages/django/db/utils.py", line 91, in __exit__
    raise dj_exc_value.with_traceback(traceback) from exc_value
  File "/home/sebastian11/venv/lib/python3.12/site-packages/django/db/backends/utils.py", line 105, in _execute
    return self.cursor.execute(sql, params)
           ^^^^^^^^^^^^^^^^^^^^^^^^^^^^^^^^
  File "/home/sebastian11/venv/lib/python3.12/site-packages/django/db/backends/sqlite3/base.py", line 360, in execute
    return super().execute(query, params)
           ^^^^^^^^^^^^^^^^^^^^^^^^^^^^^^
django.db.utils.OperationalError: attempt to write a readonly database
Internal Server Error: /excel/upload/
Traceback (most recent call last):
  File "/home/sebastian11/venv/lib/python3.12/site-packages/django/db/backends/utils.py", line 105, in _execute
    return self.cursor.execute(sql, params)
           ^^^^^^^^^^^^^^^^^^^^^^^^^^^^^^^^
  File "/home/sebastian11/venv/lib/python3.12/site-packages/django/db/backends/sqlite3/base.py", line 360, in execute
    return super().execute(query, params)
           ^^^^^^^^^^^^^^^^^^^^^^^^^^^^^^
sqlite3.OperationalError: attempt to write a readonly database

The above exception was the direct cause of the following exception:

Traceback (most recent call last):
  File "/home/sebastian11/venv/lib/python3.12/site-packages/django/core/handlers/exception.py", line 55, in inner
    response = get_response(request)
               ^^^^^^^^^^^^^^^^^^^^^
  File "/home/sebastian11/venv/lib/python3.12/site-packages/django/core/handlers/base.py", line 197, in _get_response
    response = wrapped_callback(request, *callback_args, **callback_kwargs)
               ^^^^^^^^^^^^^^^^^^^^^^^^^^^^^^^^^^^^^^^^^^^^^^^^^^^^^^^^^^^^
  File "/var/www/mi_django_app/excel_processor/views.py", line 152, in upload_excel_web
    excel_obj_3_7 = ExcelProcess.objects.create(archivo=archivo, consecutivo=consecutivo_3_7)
                    ^^^^^^^^^^^^^^^^^^^^^^^^^^^^^^^^^^^^^^^^^^^^^^^^^^^^^^^^^^^^^^^^^^^^^^^^^
  File "/home/sebastian11/venv/lib/python3.12/site-packages/django/db/models/manager.py", line 87, in manager_method
    return getattr(self.get_queryset(), name)(*args, **kwargs)
           ^^^^^^^^^^^^^^^^^^^^^^^^^^^^^^^^^^^^^^^^^^^^^^^^^^^
  File "/home/sebastian11/venv/lib/python3.12/site-packages/django/db/models/query.py", line 663, in create
    obj.save(force_insert=True, using=self.db)
  File "/home/sebastian11/venv/lib/python3.12/site-packages/django/db/models/base.py", line 902, in save
    self.save_base(
  File "/home/sebastian11/venv/lib/python3.12/site-packages/django/db/models/base.py", line 1008, in save_base
    updated = self._save_table(
              ^^^^^^^^^^^^^^^^^
  File "/home/sebastian11/venv/lib/python3.12/site-packages/django/db/models/base.py", line 1169, in _save_table
    results = self._do_insert(
              ^^^^^^^^^^^^^^^^
  File "/home/sebastian11/venv/lib/python3.12/site-packages/django/db/models/base.py", line 1210, in _do_insert
    return manager._insert(
           ^^^^^^^^^^^^^^^^
  File "/home/sebastian11/venv/lib/python3.12/site-packages/django/db/models/manager.py", line 87, in manager_method
    return getattr(self.get_queryset(), name)(*args, **kwargs)
           ^^^^^^^^^^^^^^^^^^^^^^^^^^^^^^^^^^^^^^^^^^^^^^^^^^^
  File "/home/sebastian11/venv/lib/python3.12/site-packages/django/db/models/query.py", line 1864, in _insert
    return query.get_compiler(using=using).execute_sql(returning_fields)
           ^^^^^^^^^^^^^^^^^^^^^^^^^^^^^^^^^^^^^^^^^^^^^^^^^^^^^^^^^^^^^
  File "/home/sebastian11/venv/lib/python3.12/site-packages/django/db/models/sql/compiler.py", line 1882, in execute_sql
    cursor.execute(sql, params)
  File "/home/sebastian11/venv/lib/python3.12/site-packages/django/db/backends/utils.py", line 79, in execute
    return self._execute_with_wrappers(
           ^^^^^^^^^^^^^^^^^^^^^^^^^^^^
  File "/home/sebastian11/venv/lib/python3.12/site-packages/django/db/backends/utils.py", line 92, in _execute_with_wrappers
    return executor(sql, params, many, context)
           ^^^^^^^^^^^^^^^^^^^^^^^^^^^^^^^^^^^^
  File "/home/sebastian11/venv/lib/python3.12/site-packages/django/db/backends/utils.py", line 100, in _execute
    with self.db.wrap_database_errors:
  File "/home/sebastian11/venv/lib/python3.12/site-packages/django/db/utils.py", line 91, in __exit__
    raise dj_exc_value.with_traceback(traceback) from exc_value
  File "/home/sebastian11/venv/lib/python3.12/site-packages/django/db/backends/utils.py", line 105, in _execute
    return self.cursor.execute(sql, params)
           ^^^^^^^^^^^^^^^^^^^^^^^^^^^^^^^^
  File "/home/sebastian11/venv/lib/python3.12/site-packages/django/db/backends/sqlite3/base.py", line 360, in execute
    return super().execute(query, params)
           ^^^^^^^^^^^^^^^^^^^^^^^^^^^^^^
django.db.utils.OperationalError: attempt to write a readonly database
Not Found: /favicon.ico
Internal Server Error: /excel/upload/
Traceback (most recent call last):
  File "/home/sebastian11/venv/lib/python3.12/site-packages/django/db/backends/utils.py", line 105, in _execute
    return self.cursor.execute(sql, params)
           ^^^^^^^^^^^^^^^^^^^^^^^^^^^^^^^^
  File "/home/sebastian11/venv/lib/python3.12/site-packages/django/db/backends/sqlite3/base.py", line 360, in execute
    return super().execute(query, params)
           ^^^^^^^^^^^^^^^^^^^^^^^^^^^^^^
sqlite3.OperationalError: attempt to write a readonly database

The above exception was the direct cause of the following exception:

Traceback (most recent call last):
  File "/home/sebastian11/venv/lib/python3.12/site-packages/django/core/handlers/exception.py", line 55, in inner
    response = get_response(request)
               ^^^^^^^^^^^^^^^^^^^^^
  File "/home/sebastian11/venv/lib/python3.12/site-packages/django/core/handlers/base.py", line 197, in _get_response
    response = wrapped_callback(request, *callback_args, **callback_kwargs)
               ^^^^^^^^^^^^^^^^^^^^^^^^^^^^^^^^^^^^^^^^^^^^^^^^^^^^^^^^^^^^
  File "/var/www/mi_django_app/excel_processor/views.py", line 152, in upload_excel_web
    excel_obj_3_7 = ExcelProcess.objects.create(archivo=archivo, consecutivo=consecutivo_3_7)
                    ^^^^^^^^^^^^^^^^^^^^^^^^^^^^^^^^^^^^^^^^^^^^^^^^^^^^^^^^^^^^^^^^^^^^^^^^^
  File "/home/sebastian11/venv/lib/python3.12/site-packages/django/db/models/manager.py", line 87, in manager_method
    return getattr(self.get_queryset(), name)(*args, **kwargs)
           ^^^^^^^^^^^^^^^^^^^^^^^^^^^^^^^^^^^^^^^^^^^^^^^^^^^
  File "/home/sebastian11/venv/lib/python3.12/site-packages/django/db/models/query.py", line 663, in create
    obj.save(force_insert=True, using=self.db)
  File "/home/sebastian11/venv/lib/python3.12/site-packages/django/db/models/base.py", line 902, in save
    self.save_base(
  File "/home/sebastian11/venv/lib/python3.12/site-packages/django/db/models/base.py", line 1008, in save_base
    updated = self._save_table(
              ^^^^^^^^^^^^^^^^^
  File "/home/sebastian11/venv/lib/python3.12/site-packages/django/db/models/base.py", line 1169, in _save_table
    results = self._do_insert(
              ^^^^^^^^^^^^^^^^
  File "/home/sebastian11/venv/lib/python3.12/site-packages/django/db/models/base.py", line 1210, in _do_insert
    return manager._insert(
           ^^^^^^^^^^^^^^^^
  File "/home/sebastian11/venv/lib/python3.12/site-packages/django/db/models/manager.py", line 87, in manager_method
    return getattr(self.get_queryset(), name)(*args, **kwargs)
           ^^^^^^^^^^^^^^^^^^^^^^^^^^^^^^^^^^^^^^^^^^^^^^^^^^^
  File "/home/sebastian11/venv/lib/python3.12/site-packages/django/db/models/query.py", line 1864, in _insert
    return query.get_compiler(using=using).execute_sql(returning_fields)
           ^^^^^^^^^^^^^^^^^^^^^^^^^^^^^^^^^^^^^^^^^^^^^^^^^^^^^^^^^^^^^
  File "/home/sebastian11/venv/lib/python3.12/site-packages/django/db/models/sql/compiler.py", line 1882, in execute_sql
    cursor.execute(sql, params)
  File "/home/sebastian11/venv/lib/python3.12/site-packages/django/db/backends/utils.py", line 79, in execute
    return self._execute_with_wrappers(
           ^^^^^^^^^^^^^^^^^^^^^^^^^^^^
  File "/home/sebastian11/venv/lib/python3.12/site-packages/django/db/backends/utils.py", line 92, in _execute_with_wrappers
    return executor(sql, params, many, context)
           ^^^^^^^^^^^^^^^^^^^^^^^^^^^^^^^^^^^^
  File "/home/sebastian11/venv/lib/python3.12/site-packages/django/db/backends/utils.py", line 100, in _execute
    with self.db.wrap_database_errors:
  File "/home/sebastian11/venv/lib/python3.12/site-packages/django/db/utils.py", line 91, in __exit__
    raise dj_exc_value.with_traceback(traceback) from exc_value
  File "/home/sebastian11/venv/lib/python3.12/site-packages/django/db/backends/utils.py", line 105, in _execute
    return self.cursor.execute(sql, params)
           ^^^^^^^^^^^^^^^^^^^^^^^^^^^^^^^^
  File "/home/sebastian11/venv/lib/python3.12/site-packages/django/db/backends/sqlite3/base.py", line 360, in execute
    return super().execute(query, params)
           ^^^^^^^^^^^^^^^^^^^^^^^^^^^^^^
django.db.utils.OperationalError: attempt to write a readonly database
Not Found: /favicon.ico
Not Found: /favicon.ico
Internal Server Error: /excel/upload/
Traceback (most recent call last):
  File "/home/sebastian11/venv/lib/python3.12/site-packages/django/db/backends/utils.py", line 105, in _execute
    return self.cursor.execute(sql, params)
           ^^^^^^^^^^^^^^^^^^^^^^^^^^^^^^^^
  File "/home/sebastian11/venv/lib/python3.12/site-packages/django/db/backends/sqlite3/base.py", line 360, in execute
    return super().execute(query, params)
           ^^^^^^^^^^^^^^^^^^^^^^^^^^^^^^
sqlite3.OperationalError: attempt to write a readonly database

The above exception was the direct cause of the following exception:

Traceback (most recent call last):
  File "/home/sebastian11/venv/lib/python3.12/site-packages/django/core/handlers/exception.py", line 55, in inner
    response = get_response(request)
               ^^^^^^^^^^^^^^^^^^^^^
  File "/home/sebastian11/venv/lib/python3.12/site-packages/django/core/handlers/base.py", line 197, in _get_response
    response = wrapped_callback(request, *callback_args, **callback_kwargs)
               ^^^^^^^^^^^^^^^^^^^^^^^^^^^^^^^^^^^^^^^^^^^^^^^^^^^^^^^^^^^^
  File "/var/www/mi_django_app/excel_processor/views.py", line 152, in upload_excel_web
    excel_obj_3_7 = ExcelProcess.objects.create(archivo=archivo, consecutivo=consecutivo_3_7)
                    ^^^^^^^^^^^^^^^^^^^^^^^^^^^^^^^^^^^^^^^^^^^^^^^^^^^^^^^^^^^^^^^^^^^^^^^^^
  File "/home/sebastian11/venv/lib/python3.12/site-packages/django/db/models/manager.py", line 87, in manager_method
    return getattr(self.get_queryset(), name)(*args, **kwargs)
           ^^^^^^^^^^^^^^^^^^^^^^^^^^^^^^^^^^^^^^^^^^^^^^^^^^^
  File "/home/sebastian11/venv/lib/python3.12/site-packages/django/db/models/query.py", line 663, in create
    obj.save(force_insert=True, using=self.db)
  File "/home/sebastian11/venv/lib/python3.12/site-packages/django/db/models/base.py", line 902, in save
    self.save_base(
  File "/home/sebastian11/venv/lib/python3.12/site-packages/django/db/models/base.py", line 1008, in save_base
    updated = self._save_table(
              ^^^^^^^^^^^^^^^^^
  File "/home/sebastian11/venv/lib/python3.12/site-packages/django/db/models/base.py", line 1169, in _save_table
    results = self._do_insert(
              ^^^^^^^^^^^^^^^^
  File "/home/sebastian11/venv/lib/python3.12/site-packages/django/db/models/base.py", line 1210, in _do_insert
    return manager._insert(
           ^^^^^^^^^^^^^^^^
  File "/home/sebastian11/venv/lib/python3.12/site-packages/django/db/models/manager.py", line 87, in manager_method
    return getattr(self.get_queryset(), name)(*args, **kwargs)
           ^^^^^^^^^^^^^^^^^^^^^^^^^^^^^^^^^^^^^^^^^^^^^^^^^^^
  File "/home/sebastian11/venv/lib/python3.12/site-packages/django/db/models/query.py", line 1864, in _insert
    return query.get_compiler(using=using).execute_sql(returning_fields)
           ^^^^^^^^^^^^^^^^^^^^^^^^^^^^^^^^^^^^^^^^^^^^^^^^^^^^^^^^^^^^^
  File "/home/sebastian11/venv/lib/python3.12/site-packages/django/db/models/sql/compiler.py", line 1882, in execute_sql
    cursor.execute(sql, params)
  File "/home/sebastian11/venv/lib/python3.12/site-packages/django/db/backends/utils.py", line 79, in execute
    return self._execute_with_wrappers(
           ^^^^^^^^^^^^^^^^^^^^^^^^^^^^
  File "/home/sebastian11/venv/lib/python3.12/site-packages/django/db/backends/utils.py", line 92, in _execute_with_wrappers
    return executor(sql, params, many, context)
           ^^^^^^^^^^^^^^^^^^^^^^^^^^^^^^^^^^^^
  File "/home/sebastian11/venv/lib/python3.12/site-packages/django/db/backends/utils.py", line 100, in _execute
    with self.db.wrap_database_errors:
  File "/home/sebastian11/venv/lib/python3.12/site-packages/django/db/utils.py", line 91, in __exit__
    raise dj_exc_value.with_traceback(traceback) from exc_value
  File "/home/sebastian11/venv/lib/python3.12/site-packages/django/db/backends/utils.py", line 105, in _execute
    return self.cursor.execute(sql, params)
           ^^^^^^^^^^^^^^^^^^^^^^^^^^^^^^^^
  File "/home/sebastian11/venv/lib/python3.12/site-packages/django/db/backends/sqlite3/base.py", line 360, in execute
    return super().execute(query, params)
           ^^^^^^^^^^^^^^^^^^^^^^^^^^^^^^
django.db.utils.OperationalError: attempt to write a readonly database
Watching for file changes with StatReloader
"GET /excel/upload/ HTTP/1.0" 200 1301
"GET /excel/upload/ HTTP/1.0" 200 1301
Forbidden (Origin checking failed - https://172.16.4.153 does not match any trusted origins.): /excel/upload/
"POST /excel/upload/ HTTP/1.0" 403 1025
"GET /excel/ HTTP/1.1" 200 1336
Not Found: /favicon.ico
"GET /favicon.ico HTTP/1.1" 404 179
"GET /excel/upload/ HTTP/1.1" 200 1301
"POST /excel/upload/ HTTP/1.1" 200 1696
Not Found: /media/planilla_45.pdf
"GET /media/planilla_45.pdf HTTP/1.1" 404 179
Not Found: /media/planilla_46.pdf
"GET /media/planilla_46.pdf HTTP/1.1" 404 179
Forbidden (Origin checking failed - https://172.16.4.153 does not match any trusted origins.): /excel/upload/
"POST /excel/upload/ HTTP/1.0" 403 1025
"GET /excel/upload/ HTTP/1.1" 200 1301
"POST /excel/upload/ HTTP/1.1" 200 1696
"GET /excel/upload/ HTTP/1.1" 200 1301
Not Found: /media/planilla_47.pdf
"GET /media/planilla_47.pdf HTTP/1.1" 404 179
"GET /excel/upload/ HTTP/1.1" 200 1301
"GET /excel/ HTTP/1.1" 200 1336
"GET /excel/upload/ HTTP/1.1" 200 1301
Not Found: /media/planilla_49.pdf
Not Found: /media/planilla_48.pdf
Not Found: /media/planilla_47.pdf
Not Found: /media/planilla_49.pdf
Not Found: /media/planilla_49.pdf
